<mujoco model="xarm6_with_gripper">
    <compiler   angle="radian" 
                texturedir="../textures/"
                meshdir="meshes_mujoco/" />

    <option     timestep="2e-3"
                iterations="10"
                tolerance="1e-10"
                impratio="20"/>

    <size njmax="500" nconmax="100" />

    <visual>
        <map fogstart="3" fogend="5" znear="0.001"/>
        <quality shadowsize="1024"/>
        <scale framelength="0.1"
               framewidth="0.005"
               contactwidth="0.1"
               contactheight="0.005"
               forcewidth="0.01"
               />
    </visual>

    <asset>
        <mesh name="base" file="base.stl" />
        <mesh name="link1" file="link1.stl" />
        <mesh name="link2" file="link2.stl" />
        <mesh name="link3" file="link3.stl" />
        <mesh name="link4" file="link4.stl" />
        <mesh name="link5" file="link5.stl" />
        <mesh name="link6" file="link6.stl" />
        <mesh name="base_link" file="base_link.STL" />
        <mesh name="left_outer_knuckle" file="left_outer_knuckle.STL" />
        <mesh name="left_finger" file="left_finger.STL" />
        <mesh name="left_inner_knuckle" file="left_inner_knuckle.STL" />
        <mesh name="right_outer_knuckle" file="right_outer_knuckle.STL" />
        <mesh name="right_finger" file="right_finger.STL" />
        <mesh name="right_inner_knuckle" file="right_inner_knuckle.STL" />

        <texture name="floor_tex"   type="2d"        builtin="checker" rgb1=".2 .3 .4" rgb2=".1 .2 .3" width="100" height="100"/>
        <texture name="wood"        type="cube"     file="wood2.png"/>
        <texture name="metal"        type="cube"     file="metal2.png"/>
        <texture name="grass"        type="cube"     file="grass.png"/>

        <material name='floor_mat'      texture="floor_tex"  shininess="0.8" texrepeat="10 10" specular="0.7"  reflectance="0.5" />
        <material name="bench_mat"      texture="metal"   shininess="0.1" specular="0.5" reflectance="0.2"/>
        <material name="tablecube"      texture="wood" rgba=".8 .8 .8 1"/>
        <material name="grass_mat"      texture="grass" rgba=".8 .8 .8 1"/>
    </asset>


    <worldbody>

        <!--Lighting parameters-->
        <light name="light2" mode="targetbody" target="link1" castshadow='false' directional="true" pos="1 1 4" />
        <light name="light3" mode="targetbody" target="link1" castshadow='false' directional="true" pos="-1 -1 4" />
        <light name="light4" mode="targetbody" target="link1" castshadow='false' directional="true" pos="1 -1 4" />
        <light name="light5" mode="targetbody" target="link1" castshadow='false' directional="true" pos="-1 1 4" />

        <!--Camera parameters-->
        <!--<camera name="main1" mode="targetbodycom" target="tree_link" pos="0 0 2.7" euler="0 0.57 0.57"/> -->
        <!--Floor Property-->
        <geom name='floor' material="floor_mat" pos='0 0 0' size='10 10 0.1'  type='plane' />


        <body name="obst_box_1" pos="0.4 0.2 1.075">
            <geom size=".01 .2 .15" rgba="1 1 0 1" type="box" material="bench_mat"/>
            <!-- <joint pos="0 0 0" type="free"/> -->
        </body>   

        <body name="ball" pos="0.6 0.2 1.075">
            <geom mass="1.0" rgba="1 0 0 1" size="0.075 0.4 0.2" type="sphere"/>
            <!-- <joint pos="0 0 0" type="free"/> -->
        </body>   
<!--         <body name="box_link" pos="0 0 0.435">

            <geom size=".29 .19 .03" pos ="0 0 0.4" type="box" material="bench_mat"/>
            <geom size=".29 .19 .03" pos ="0 0 -0.2" type="box" material="bench_mat"/>
            <geom size=".04 .04 .435" pos =".26 .16 0" type="box" material="bench_mat"/>
            <geom size=".04 .04 .435" pos ="-.26 .16 0" type="box" material="bench_mat"/>
            <geom size=".04 .04 .435" pos =".26 -.16 0" type="box" material="bench_mat"/>
            <geom size=".04 .04 .435" pos ="-.26 -.16 0" type="box" material="bench_mat"/>

            <geom size="1 1 1" pos ="0 5 0.565" type="box" material="tablecube"/>
            <geom size="1 1 1" pos ="0 -5 0.565" type="box" material="grass_mat"/>

            <inertial pos="0 0 0" mass="1000" diaginertia="0 0 0" /> -->


        <body name="box_link" pos="0 0 0.5">
            <geom size="1 1 0.5" pos ="0 0 0" type="box" material="tablecube"/>


            <body name="stick_01" pos="1 1 1.5">
                <geom size="0.01 1"  type="cylinder" rgba="1 0 0 1"/>
            </body>              
            <body name="stick_02" pos="-1 -1 1.5">
                <geom size="0.01 1"  type="cylinder" rgba="0 1 0 1"/>
            </body>    
            <body name="stick_03" pos="-1 1 1.5">
                <geom size="0.01 1"  type="cylinder" rgba="0 0 1 1"/>
            </body>    
            <body name="stick_04" pos="1 -1 1.5">
                <geom size="0.01 1"  type="cylinder" rgba="1 1 0 1"/>
            </body>    


            <body name="stick_05" pos="0 1 1.5">
                <geom size="0.01 1"  type="cylinder" rgba="0 1 1 1"/>
            </body>     

            <body name="stick_06" pos="0 -1 1.5">
                <geom size="0.01 1"  type="cylinder" rgba="1 0 1 1"/>
            </body>   

            <body name="stick_07" pos="1 0 1.5">
                <geom size="0.01 1"  type="cylinder" rgba="1 0.5 0 1"/>
            </body>    

            <body name="stick_08" pos="-1 0 1.5">
                <geom size="0.01 1"  type="cylinder" rgba="1 0.5 0.5 1"/>
            </body>  


            <body name="robot_pedestal" pos="0.0 0.0 0.6">
                <geom size=".1 .1 .1"  type="box" material="grass_mat"/>
                <!-- <joint pos="0 0 0" type="free"/> -->
 



                <!-- <geom type="mesh" contype="0" pos="0 0 0.8" conaffinity="0" group="1" rgba="1 1 1 1" mesh="base" /> -->
                <!-- <geom type="mesh" rgba="1 1 1 1" mesh="base" /> -->
                    <body name="base" pos="0 0 0.0">
                        <!-- <inertial pos="0.03531 -0.21398 0.03386" quat="0.71118 0.614686 0.139936 -0.311132" mass="1.71" diaginertia="0.017867 0.017867 0.017867" /> -->
                        <geom type="mesh" contype="0" conaffinity="0" group="1" rgba="1 1 1 1" mesh="base" />
                        <geom type="mesh" rgba="1 1 1 1" mesh="base" />

                        <body name="link1" pos="0 0 0.267">
                        <!-- <body name="link1" pos="0 0 0.267"> -->
                            <inertial pos="-0.002 0.02692 -0.01332" quat="0.983139 0.180751 -0.00455228 0.0272976" mass="2.16" diaginertia="0.00539487 0.00519906 0.00281397" />
                            <joint name="joint1" pos="0 0 0" axis="0 0 1" limited="true" range="-6.28319 6.28319" damping="1" frictionloss="1" />
                            <geom type="mesh" contype="0" conaffinity="0" group="1" rgba="1 1 1 1" mesh="link1" />
                            <geom type="mesh" rgba="1 1 1 1" mesh="link1" />

                            <body name="link2" pos="0 0 0" quat="0.707105 -0.707108 0 0">
                                <inertial pos="0.03531 -0.21398 0.03386" quat="0.71118 0.614686 0.139936 -0.311132" mass="1.71" diaginertia="0.017867 0.017867 0.017867" />
                                <joint name="joint2" pos="0 0 0" axis="0 0 1" limited="true" range="-2.059 2.0944" damping="1" frictionloss="1" />
                                <geom type="mesh" contype="0" conaffinity="0" group="1" rgba="1 1 1 1" mesh="link2" />
                                <geom type="mesh" rgba="1 1 1 1" mesh="link2" />

                                <body name="link3" pos="0.0535 -0.2845 0">
                                    <inertial pos="0.06781 0.10749 0.01457" quat="0.119516 0.409082 -0.734824 0.527638" mass="1.384" diaginertia="0.004543 0.004543 0.004543" />
                                    <joint name="joint3" pos="0 0 0" axis="0 0 1" limited="true" range="-3.927 0.19198" damping="1" frictionloss="1" />
                                    <geom type="mesh" contype="0" conaffinity="0" group="1" rgba="1 1 1 1" mesh="link3" />
                                    <geom type="mesh" rgba="1 1 1 1" mesh="link3" />

                                    <body name="link4" pos="0.0775 0.3425 0" quat="0.707105 -0.707108 0 0">
                                        <inertial pos="-0.00021 0.02578 -0.02538" quat="0.994019 0.0752563 -0.00686804 0.0788347" mass="1.115" diaginertia="0.00440091 0.00406855 0.00103407" />
                                        <joint name="joint4" pos="0 0 0" axis="0 0 1" limited="true" range="-6.28319 6.28319" damping="1" frictionloss="1" />
                                        <geom type="mesh" contype="0" conaffinity="0" group="1" rgba="1 1 1 1" mesh="link4" />
                                        <geom type="mesh" rgba="1 1 1 1" mesh="link4" />

                                        <body name="link5" pos="0 0 0" quat="0.707105 0.707108 0 0">
                                            <inertial pos="0.05428 0.01781 0.00543" quat="-0.0766302 0.578118 -0.269638 0.766291" mass="1.275" diaginertia="0.00289757 0.0023276 0.000951789" />
                                            <joint name="joint5" pos="0 0 0" axis="0 0 1" limited="true" range="-1.69297 3.14159" damping="1" frictionloss="1" />
                                            <geom type="mesh" contype="0" conaffinity="0" group="1" rgba="1 1 1 1" mesh="link5" />
                                            <geom type="mesh" rgba="1 1 1 1" mesh="link5" />

                                            <body name="link6" pos="0.076 0.097 0" quat="0.707105 -0.707108 0 0">
                                                <inertial pos="-0.000544662 -0.00143065 0.0383418" quat="0.999975 0.0030188 -0.00631554 0.000998731" mass="0.65116" diaginertia="0.000818872 0.000680759 0.00033665" />
                                                <joint name="joint6" pos="0 0 0" axis="0 0 1" limited="true" range="-6.28319 6.28319" damping="1" frictionloss="1" />
                                                <geom type="mesh" contype="0" conaffinity="0" group="1" rgba="0.753 0.753 0.753 1" mesh="link6" />
                                                <geom type="mesh" rgba="0.753 0.753 0.753 1" mesh="link6" />

                                                <body name="intel_cam" pos="0.0 0.0 0.025">
                                                    <geom size="0.025 0.090 0.025" pos ="0 0 0" type="box" material="bench_mat"/>
                                                    <inertial pos="0 0 0" quat="0.983139 0.180751 -0.00455228 0.0272976" mass="0.255" diaginertia="0.00539487 0.00519906 0.00281397" />
                                                    <light name="light_cam" mode="fixed" directional="false" pos="0 0 0.5" />
                                                    <camera name="intel_cam" mode="fixed"  fovy= "100" pos="0.0 0 0.0" euler="0 3.14 0"/>
                                                </body>


    <!--                                         <geom type="mesh" contype="0" conaffinity="0" group="1" rgba="1 1 1 1" mesh="base_link" />
                                                <geom type="mesh" rgba="1 1 1 1" mesh="base_link" />

                                                <body name="left_outer_knuckle" pos="0 0.035 0.059098">
                                                    <inertial pos="0 0.021559 0.015181" quat="0.47789 0.87842 0 0" mass="0.033618" diaginertia="1.9111e-05 1.79089e-05 1.90167e-06" />
                                                    <joint name="drive_joint" pos="0 0 0" axis="1 0 0" limited="true" range="0 0.85" />
                                                    <geom type="mesh" contype="0" conaffinity="0" group="1" rgba="0.753 0.753 0.753 1" mesh="left_outer_knuckle" />
                                                    <geom type="mesh" rgba="0.753 0.753 0.753 1" mesh="left_outer_knuckle" />
                                                    <body name="left_finger" pos="0 0.035465 0.042039">

                                                        <inertial pos="0 -0.016413 0.029258" quat="0.697634 0.115353 -0.115353 0.697634" mass="0.048304" diaginertia="1.88037e-05 1.7493e-05 3.56792e-06" />
                                                        <joint name="left_finger_joint" pos="0 0 0" axis="-1 0 0" limited="true" range="0 0.85" />
                                                        <geom type="mesh" contype="0" conaffinity="0" group="1" rgba="0.753 0.753 0.753 1" mesh="left_finger" />
                                                        <geom type="mesh" rgba="0.753 0.753 0.753 1" mesh="left_finger" />
                                                    </body>
                                                </body>
                                                <body name="left_inner_knuckle" pos="0 0.02 0.074098">
                                                    <inertial pos="1.86601e-06 0.0220468 0.0261335" quat="0.664139 -0.242732 0.242713 0.664146" mass="0.0230126" diaginertia="8.34216e-06 6.0949e-06 2.75601e-06" />
                                                    <joint name="left_inner_knuckle_joint" pos="0 0 0" axis="1 0 0" limited="true" range="0 0.85" />
                                                    <geom type="mesh" contype="0" conaffinity="0" group="1" rgba="0.753 0.753 0.753 1" mesh="left_inner_knuckle" />
                                                    <geom type="mesh" rgba="0.753 0.753 0.753 1" mesh="left_inner_knuckle" />
                                                </body>
                                                <body name="right_outer_knuckle" pos="0 -0.035 0.059098">
                                                    <inertial pos="0 -0.021559 0.015181" quat="0.87842 0.47789 0 0" mass="0.033618" diaginertia="1.9111e-05 1.79089e-05 1.90167e-06" />
                                                    <joint name="right_outer_knuckle_joint" pos="0 0 0" axis="-1 0 0" limited="true" range="0 0.85" />
                                                    <geom type="mesh" contype="0" conaffinity="0" group="1" rgba="0.753 0.753 0.753 1" mesh="right_outer_knuckle" />
                                                    <geom type="mesh" rgba="0.753 0.753 0.753 1" mesh="right_outer_knuckle" />
                                                    <body name="right_finger" pos="0 -0.035465 0.042039">
                                                        <inertial pos="0 0.016413 0.029258" quat="0.697634 -0.115356 0.115356 0.697634" mass="0.048304" diaginertia="1.88038e-05 1.7493e-05 3.56779e-06" />
                                                        <joint name="right_finger_joint" pos="0 0 0" axis="1 0 0" limited="true" range="0 0.85" />
                                                        <geom type="mesh" contype="0" conaffinity="0" group="1" rgba="0.753 0.753 0.753 1" mesh="right_finger" />
                                                        <geom type="mesh" rgba="0.753 0.753 0.753 1" mesh="right_finger" />
                                                    </body>
                                                </body>
                                                <body name="right_inner_knuckle" pos="0 -0.02 0.074098">
                                                    <inertial pos="1.866e-06 -0.022047 0.026133" quat="0.66415 0.242702 -0.242721 0.664144" mass="0.023013" diaginertia="8.34209e-06 6.0949e-06 2.75601e-06" />
                                                    <joint name="right_inner_knuckle_joint" pos="0 0 0" axis="-1 0 0" limited="true" range="0 0.85" />
                                                    <geom type="mesh" contype="0" conaffinity="0" group="1" rgba="0.753 0.753 0.753 1" mesh="right_inner_knuckle" />
                                                    <geom type="mesh" rgba="0.753 0.753 0.753 1" mesh="right_inner_knuckle" />
                                                </body> -->
                                        </body>
                                    </body>
                                </body>
                            </body>
                        </body>
                    </body>
                </body>   
            </body>            
        </body>


    </worldbody>


    <!--ACTUATORS-->
    <actuator>
        <motor name='motor_joint1' ctrllimited="true" ctrlrange="-2 2" joint='joint1' gear="10"/>
        <motor name='motor_joint2' ctrllimited="true" ctrlrange="-2 2" joint='joint2' gear="10"/>
        <motor name='motor_joint3' ctrllimited="true" ctrlrange="-2 2" joint='joint3' gear="10"/>
        <motor name='motor_joint4' ctrllimited="true" ctrlrange="-2 2" joint='joint4' gear="10"/>
        <motor name='motor_joint5' ctrllimited="true" ctrlrange="-2 2" joint='joint5' gear="10"/>
        <motor name='motor_joint6' ctrllimited="true" ctrlrange="-2 2" joint='joint6' gear="10"/>
    </actuator>

    <sensor>
        <jointpos name="sp1" joint="joint1" />
        <jointpos name="sp2" joint="joint2" />
        <jointpos name="sp3" joint="joint3" />
        <jointpos name="sp4" joint="joint4" />
        <jointpos name="sp5" joint="joint5" />
        <jointpos name="sp6" joint="joint6" />
        <jointvel name="sv1" joint="joint1" />
        <jointvel name="sv2" joint="joint2" />
        <jointvel name="sv3" joint="joint3" />
        <jointvel name="sv4" joint="joint4" />
        <jointvel name="sv5" joint="joint5" />
        <jointvel name="sv6" joint="joint6" />
    </sensor>

</mujoco>
